import pytest
from unittest import mock
from PIL import Image
import asyncio

# Mocking Class Initialization
class Hello:
    def __init__(self, name):
        self.name = name

@mock.patch.object(Hello, '__init__', return_value=None)
def test_hello_init(mocked_init):
    hello = Hello('world')
    mocked_init.assert_called_once_with('world')


# Mocking Error Handling
def risky_operation():
    try:
        1 / 0
    except ZeroDivisionError as e:
        print('Exception caught:', e)
        return 'failed'
    return 'success'

@mock.patch('builtins.print')
def test_risky_operation(mocked_print):
    assert risky_operation() == 'failed'
    mocked_print.assert_called_once_with('Exception caught:', ZeroDivisionError('division by zero'))


# Mocking Image's save method and Async Calls
class DummyClass:
    async def dummy_async_func(self, value):
        return value * 2

def save_image(image_path, new_image_path):
    with Image.open(image_path) as img:
        img.save(new_image_path)

@mock.patch('builtins.open', new_callable=mock.mock_open)
@mock.patch('PIL.Image.Image.save')
@mock.patch.object(DummyClass, 'dummy_async_func', new_callable=mock.AsyncMock)
def test_async_and_image_manipulation(mocked_async_func, mock_save, mock_open):
    # Testing async method
    loop = asyncio.get_event_loop()
    dummy_obj = DummyClass()
    assert loop.run_until_complete(dummy_obj.dummy_async_func(21)) == 42
    mocked_async_func.assert_called_once_with(21)

    # Testing PIL's image save
    mock_img = mock.MagicMock(spec=Image.Image)
    mock_open.return_value.__enter__.return_value = mock_img
    test_old_img_path = '/path/to/old/img'
    test_new_img_path = '/path/to/new/img'
    save_image(test_old_img_path, test_new_img_path)
    mock_open.assert_any_call(test_old_img_path)
    mock_open.assert_any_call(test_new_img_path)
    mock_img.__enter__.assert_called_once()
    mock_save.assert_called_once_with(test_new_img_path)

if __name__ == "__main__":
    pytest.main([__file__])